Workbook

Sheet MARZO
A1: MARZO 2025
A2: FECHA | B2: No DOCUMENTO | C2: CONSECUTIVO | D2: NIT | E2: RAZON SOCIAL | F2: PRIMER NOMBRE | G2: SEGUNDO NOMBRE | H2: PRIMER APELLIDO | I2: SEGUNDO APELLIDO | J2: DIRECCION | K2: TELEFONO | L2: CORREO | M2: VALOR | N2: TIPO DE GASTO
A3: 45718 | B3: 3963 | D3: =IFERROR(VLOOKUP($E3,'BASE DE DATOS'!$A:$I,2,0)," ") -> 66929745 | E3: ='BASE DE DATOS'!$A$111 -> POLLOS EL SABOR | F3: =IFERROR(VLOOKUP($D3,'BASE DE DATOS'!$B:$I,2,0),0) -> MARTHA | G3: =IFERROR(VLOOKUP($D3,'BASE DE DATOS'!$B:$I,3,0),0) -> 0 | H3: =IFERROR(VLOOKUP($D3,'BASE DE DATOS'!$B:$I,4,0),0) -> 0 | I3: =IFERROR(VLOOKUP($D3,'BASE DE DATOS'!$B:$I,5,0),0) -> 0 | J3: =IFERROR(VLOOKUP($D3,'BASE DE DATOS'!$B:$I,6,0),0) -> CL 8 12 10 | K3: =IFERROR(VLOOKUP($D3,'BASE DE DATOS'!$B:$I,7,0),0) -> 3017199935 | L3: =IFERROR(VLOOKUP($D3,'BASE DE DATOS'!$B:$I,8,0),0) -> 0 | M3: 481900 | N3: COSTO
A4: 45720 | B4: 0 | D4: =IFERROR(VLOOKUP($E4,'BASE DE DATOS'!$A:$I,2,0)," ") -> 94303413 | E4: ='BASE DE DATOS'!$A$19 -> COLANTA | F4: =IFERROR(VLOOKUP($D4,'BASE DE DATOS'!$B:$I,2,0),0) -> GUSTAVO | G4: =IFERROR(VLOOKUP($D4,'BASE DE DATOS'!$B:$I,3,0),0) -> ADOLFO | H4: =IFERROR(VLOOKUP($D4,'BASE DE DATOS'!$B:$I,4,0),0) -> CAMPO | I4: =IFERROR(VLOOKUP($D4,'BASE DE DATOS'!$B:$I,5,0),0) -> TORRES | J4: =IFERROR(VLOOKUP($D4,'BASE DE DATOS'!$B:$I,6,0),0) -> CL 6 13 04 | K4: =IFERROR(VLOOKUP($D4,'BASE DE DATOS'!$B:$I,7,0),0) -> 3136595942 | L4: =IFERROR(VLOOKUP($D4,'BASE DE DATOS'!$B:$I,8,0),0) -> 0 | M4: 490000 | N4: COSTO
A5: 45692 | B5: 0 | D5: =IFERROR(VLOOKUP($E5,'BASE DE DATOS'!$A:$I,2,0)," ") -> 0 | E5: ='BASE DE DATOS'!$A$3 -> aguacates | F5: =IFERROR(VLOOKUP($D5,'BASE DE DATOS'!$B:$I,2,0),0) -> 0 | G5: =IFERROR(VLOOKUP($D5,'BASE DE DATOS'!$B:$I,3,0),0) -> 0 | H5: =IFERROR(VLOOKUP($D5,'BASE DE DATOS'!$B:$I,4,0),0) -> 0 | I5: =IFERROR(VLOOKUP($D5,'BASE DE DATOS'!$B:$I,5,0),0) -> 0 | J5: =IFERROR(VLOOKUP($D5,'BASE DE DATOS'!$B:$I,6,0),0) -> 0 | K5: =IFERROR(VLOOKUP($D5,'BASE DE DATOS'!$B:$I,7,0),0) -> 0 | L5: =IFERROR(VLOOKUP($D5,'BASE DE DATOS'!$B:$I,8,0),0) -> 0 | M5: 248000 | N5: COSTO
A6: 45717 | B6: 6991227 | D6: =IFERROR(VLOOKUP($E6,'BASE DE DATOS'!$A:$I,2,0)," ") -> 8150048801 | E6: ='BASE DE DATOS'!$A$143 -> DISTRIBUIDORA TIENDAS Y MARCAS | F6: =IFERROR(VLOOKUP($D6,'BASE DE DATOS'!$B:$I,2,0),0) -> ELIANA | G6: =IFERROR(VLOOKUP($D6,'BASE DE DATOS'!$B:$I,3,0),0) -> MARIA | H6: =IFERROR(VLOOKUP($D6,'BASE DE DATOS'!$B:$I,4,0),0) -> 0 | I6: =IFERROR(VLOOKUP($D6,'BASE DE DATOS'!$B:$I,5,0),0) -> 0 | J6: =IFERROR(VLOOKUP($D6,'BASE DE DATOS'!$B:$I,6,0),0) -> CRA 34 31 35 BOD 2 PALMIRA | K6: =IFERROR(VLOOKUP($D6,'BASE DE DATOS'!$B:$I,7,0),0) -> 3228469553 | L6: =IFERROR(VLOOKUP($D6,'BASE DE DATOS'!$B:$I,8,0),0) -> 0 | M6: 186900 | N6: COSTO
A7: 45717 | B7: 3766 | D7: =IFERROR(VLOOKUP($E7,'BASE DE DATOS'!$A:$I,2,0)," ") -> 66929745 | E7: POLLOS EL SABOR | F7: =IFERROR(VLOOKUP($D7,'BASE DE DATOS'!$B:$I,2,0),0) -> MARTHA | G7: =IFERROR(VLOOKUP($D7,'BASE DE DATOS'!$B:$I,3,0),0) -> 0 | H7: =IFERROR(VLOOKUP($D7,'BASE DE DATOS'!$B:$I,4,0),0) -> 0 | I7: =IFERROR(VLOOKUP($D7,'BASE DE DATOS'!$B:$I,5,0),0) -> 0 | J7: =IFERROR(VLOOKUP($D7,'BASE DE DATOS'!$B:$I,6,0),0) -> CL 8 12 10 | K7: =IFERROR(VLOOKUP($D7,'BASE DE DATOS'!$B:$I,7,0),0) -> 3017199935 | L7: =IFERROR(VLOOKUP($D7,'BASE DE DATOS'!$B:$I,8,0),0) -> 0 | M7: 475600 | N7: COSTO
A8: 45717 | B8: 0 | D8: =IFERROR(VLOOKUP($E8,'BASE DE DATOS'!$A:$I,2,0)," ") -> 0 | E8: ='BASE DE DATOS'!$A$174 -> LECHUGA | F8: =IFERROR(VLOOKUP($D8,'BASE DE DATOS'!$B:$I,2,0),0) -> 0 | G8: =IFERROR(VLOOKUP($D8,'BASE DE DATOS'!$B:$I,3,0),0) -> 0 | H8: =IFERROR(VLOOKUP($D8,'BASE DE DATOS'!$B:$I,4,0),0) -> 0 | I8: =IFERROR(VLOOKUP($D8,'BASE DE DATOS'!$B:$I,5,0),0) -> 0 | J8: =IFERROR(VLOOKUP($D8,'BASE DE DATOS'!$B:$I,6,0),0) -> 0 | K8: =IFERROR(VLOOKUP($D8,'BASE DE DATOS'!$B:$I,7,0),0) -> 0 | L8: =IFERROR(VLOOKUP($D8,'BASE DE DATOS'!$B:$I,8,0),0) -> 0 | M8: 15400 | N8: COSTO
A9: 45717 | B9: 0 | D9: =IFERROR(VLOOKUP($E9,'BASE DE DATOS'!$A:$I,2,0)," ") -> 0 | E9: ='BASE DE DATOS'!$A$58 -> gastos varios caja/ descuadres | F9: =IFERROR(VLOOKUP($D9,'BASE DE DATOS'!$B:$I,2,0),0) -> 0 | G9: =IFERROR(VLOOKUP($D9,'BASE DE DATOS'!$B:$I,3,0),0) -> 0 | H9: =IFERROR(VLOOKUP($D9,'BASE DE DATOS'!$B:$I,4,0),0) -> 0 | I9: =IFERROR(VLOOKUP($D9,'BASE DE DATOS'!$B:$I,5,0),0) -> 0 | J9: =IFERROR(VLOOKUP($D9,'BASE DE DATOS'!$B:$I,6,0),0) -> 0 | K9: =IFERROR(VLOOKUP($D9,'BASE DE DATOS'!$B:$I,7,0),0) -> 0 | L9: =IFERROR(VLOOKUP($D9,'BASE DE DATOS'!$B:$I,8,0),0) -> 0 | M9: 84000 | N9: COSTO
A10: 45718 | B10: 0 | D10: =IFERROR(VLOOKUP($E10,'BASE DE DATOS'!$A:$I,2,0)," ") -> 0 | E10: ='BASE DE DATOS'!$A$176 -> MERCAFRUVER LA ECONOMIA demi pradera | F10: =IFERROR(VLOOKUP($D10,'BASE DE DATOS'!$B:$I,2,0),0) -> 0 | G10: =IFERROR(VLOOKUP($D10,'BASE DE DATOS'!$B:$I,3,0),0) -> 0 | H10: =IFERROR(VLOOKUP($D10,'BASE DE DATOS'!$B:$I,4,0),0) -> 0 | I10: =IFERROR(VLOOKUP($D10,'BASE DE DATOS'!$B:$I,5,0),0) -> 0 | J10: =IFERROR(VLOOKUP($D10,'BASE DE DATOS'!$B:$I,6,0),0) -> 0 | K10: =IFERROR(VLOOKUP($D10,'BASE DE DATOS'!$B:$I,7,0),0) -> 0 | L10: =IFERROR(VLOOKUP($D10,'BASE DE DATOS'!$B:$I,8,0),0) -> 0 | M10: 56000 | N10: COSTO
A11: 45718 | B11: 0 | D11: =IFERROR(VLOOKUP($E11,'BASE DE DATOS'!$A:$I,2,0)," ") -> 0 | E11: gastos varios caja/ descuadres | F11: =IFERROR(VLOOKUP($D11,'BASE DE DATOS'!$B:$I,2,0),0) -> 0 | G11: =IFERROR(VLOOKUP($D11,'BASE DE DATOS'!$B:$I,3,0),0) -> 0 | H11: =IFERROR(VLOOKUP($D11,'BASE DE DATOS'!$B:$I,4,0),0) -> 0 | I11: =IFERROR(VLOOKUP($D11,'BASE DE DATOS'!$B:$I,5,0),0) -> 0 | J11: =IFERROR(VLOOKUP($D11,'BASE DE DATOS'!$B:$I,6,0),0) -> 0 | K11: =IFERROR(VLOOKUP($D11,'BASE DE DATOS'!$B:$I,7,0),0) -> 0 | L11: =IFERROR(VLOOKUP($D11,'BASE DE DATOS'!$B:$I,8,0),0) -> 0 | M11: 3000 | N11: GASTO
A12: 45717 | B12: 18 | D12: =IFERROR(VLOOKUP($E12,'BASE DE DATOS'!$A:$I,2,0)," ") -> 14695845 | E12: ='BASE DE DATOS'!$A$93 -> MERCAFRUVER EL MAYORISTA | F12: =IFERROR(VLOOKUP($D12,'BASE DE DATOS'!$B:$I,2,0),0) -> EDELMIRA | G12: =IFERROR(VLOOKUP($D12,'BASE DE DATOS'!$B:$I,3,0),0) -> 0 | H12: =IFERROR(VLOOKUP($D12,'BASE DE DATOS'!$B:$I,4,0),0) -> MORALES | I12: =IFERROR(VLOOKUP($D12,'BASE DE DATOS'!$B:$I,5,0),0) -> ACOSTA | J12: =IFERROR(VLOOKUP($D12,'BASE DE DATOS'!$B:$I,6,0),0) -> ST 1 MZ 19 VILLAMARINA | K12: =IFERROR(VLOOKUP($D12,'BASE DE DATOS'!$B:$I,7,0),0) -> 3215223609 | L12: =IFERROR(VLOOKUP($D12,'BASE DE DATOS'!$B:$I,8,0),0) -> 0 | M12: 110000 | N12: COSTO
A13: 45721 | B13: 9181514 | D13: =IFERROR(VLOOKUP($E13,'BASE DE DATOS'!$A:$I,2,0)," ") -> 800249860 | E13: ='BASE DE DATOS'!$A$13 -> CELSIA COLOMBIA SA ESP | F13: =IFERROR(VLOOKUP($D13,'BASE DE DATOS'!$B:$I,2,0),0) -> NO TIENE | G13: =IFERROR(VLOOKUP($D13,'BASE DE DATOS'!$B:$I,3,0),0) -> NO TIENE | H13: =IFERROR(VLOOKUP($D13,'BASE DE DATOS'!$B:$I,4,0),0) -> NO TIENE | I13: =IFERROR(VLOOKUP($D13,'BASE DE DATOS'!$B:$I,5,0),0) -> NO TIENE | J13: =IFERROR(VLOOKUP($D13,'BASE DE DATOS'!$B:$I,6,0),0) -> CL 15 29 30 | K13: =IFERROR(VLOOKUP($D13,'BASE DE DATOS'!$B:$I,7,0),0) -> 3210000 | L13: =IFERROR(VLOOKUP($D13,'BASE DE DATOS'!$B:$I,8,0),0) -> servicioalcliente@celsia.com | M13: 508170 | N13: SERVICIOS
A14: 45720 | B14: 0 | D14: =IFERROR(VLOOKUP($E14,'BASE DE DATOS'!$A:$I,2,0)," ") -> 4712068 | E14: ='BASE DE DATOS'!$A$59 -> GERMAN TOVAR | F14: =IFERROR(VLOOKUP($D14,'BASE DE DATOS'!$B:$I,2,0),0) -> GERMAN | G14: =IFERROR(VLOOKUP($D14,'BASE DE DATOS'!$B:$I,3,0),0) -> 0 | H14: =IFERROR(VLOOKUP($D14,'BASE DE DATOS'!$B:$I,4,0),0) -> TOVAR | I14: =IFERROR(VLOOKUP($D14,'BASE DE DATOS'!$B:$I,5,0),0) -> 0 | J14: =IFERROR(VLOOKUP($D14,'BASE DE DATOS'!$B:$I,6,0),0) -> CL 6 15 03 | K14: =IFERROR(VLOOKUP($D14,'BASE DE DATOS'!$B:$I,7,0),0) -> 3168117423 | L14: =IFERROR(VLOOKUP($D14,'BASE DE DATOS'!$B:$I,8,0),0) -> 0 | M14: 600000 | N14: SERVICIOS
A15: 45720 | B15: 0 | D15: =IFERROR(VLOOKUP($E15,'BASE DE DATOS'!$A:$I,2,0)," ") -> 4712068 | E15: ='BASE DE DATOS'!$A$59 -> GERMAN TOVAR | F15: =IFERROR(VLOOKUP($D15,'BASE DE DATOS'!$B:$I,2,0),0) -> GERMAN | G15: =IFERROR(VLOOKUP($D15,'BASE DE DATOS'!$B:$I,3,0),0) -> 0 | H15: =IFERROR(VLOOKUP($D15,'BASE DE DATOS'!$B:$I,4,0),0) -> TOVAR | I15: =IFERROR(VLOOKUP($D15,'BASE DE DATOS'!$B:$I,5,0),0) -> 0 | J15: =IFERROR(VLOOKUP($D15,'BASE DE DATOS'!$B:$I,6,0),0) -> CL 6 15 03 | K15: =IFERROR(VLOOKUP($D15,'BASE DE DATOS'!$B:$I,7,0),0) -> 3168117423 | L15: =IFERROR(VLOOKUP($D15,'BASE DE DATOS'!$B:$I,8,0),0) -> 0 | M15: 600000 | N15: SERVICIOS
A16: 45721 | B16: 4105 | D16: =IFERROR(VLOOKUP($E16,'BASE DE DATOS'!$A:$I,2,0)," ") -> 66929745 | E16: POLLOS EL SABOR | F16: =IFERROR(VLOOKUP($D16,'BASE DE DATOS'!$B:$I,2,0),0) -> MARTHA | G16: =IFERROR(VLOOKUP($D16,'BASE DE DATOS'!$B:$I,3,0),0) -> 0 | H16: =IFERROR(VLOOKUP($D16,'BASE DE DATOS'!$B:$I,4,0),0) -> 0 | I16: =IFERROR(VLOOKUP($D16,'BASE DE DATOS'!$B:$I,5,0),0) -> 0 | J16: =IFERROR(VLOOKUP($D16,'BASE DE DATOS'!$B:$I,6,0),0) -> CL 8 12 10 | K16: =IFERROR(VLOOKUP($D16,'BASE DE DATOS'!$B:$I,7,0),0) -> 3017199935 | L16: =IFERROR(VLOOKUP($D16,'BASE DE DATOS'!$B:$I,8,0),0) -> 0 | M16: 474000 | N16: COSTO
A17: 45722 | B17: 290564067 | D17: =IFERROR(VLOOKUP($E17,'BASE DE DATOS'!$A:$I,2,0)," ") -> 800153993 | E17: ='BASE DE DATOS'!$A$21 -> COMCEL SA | F17: =IFERROR(VLOOKUP($D17,'BASE DE DATOS'!$B:$I,2,0),0) -> NO TIENE | G17: =IFERROR(VLOOKUP($D17,'BASE DE DATOS'!$B:$I,3,0),0) -> NO TIENE | H17: =IFERROR(VLOOKUP($D17,'BASE DE DATOS'!$B:$I,4,0),0) -> NO TIENE | I17: =IFERROR(VLOOKUP($D17,'BASE DE DATOS'!$B:$I,5,0),0) -> NO TIENE | J17: =IFERROR(VLOOKUP($D17,'BASE DE DATOS'!$B:$I,6,0),0) -> 0 | K17: =IFERROR(VLOOKUP($D17,'BASE DE DATOS'!$B:$I,7,0),0) -> 0 | L17: =IFERROR(VLOOKUP($D17,'BASE DE DATOS'!$B:$I,8,0),0) -> 0 | M17: 428999 | N17: GASTO
A18: 45721 | B18: 12 | D18: =IFERROR(VLOOKUP($E18,'BASE DE DATOS'!$A:$I,2,0)," ") -> 14695845 | E18: MERCAFRUVER EL MAYORISTA | F18: =IFERROR(VLOOKUP($D18,'BASE DE DATOS'!$B:$I,2,0),0) -> EDELMIRA | G18: =IFERROR(VLOOKUP($D18,'BASE DE DATOS'!$B:$I,3,0),0) -> 0 | H18: =IFERROR(VLOOKUP($D18,'BASE DE DATOS'!$B:$I,4,0),0) -> MORALES | I18: =IFERROR(VLOOKUP($D18,'BASE DE DATOS'!$B:$I,5,0),0) -> ACOSTA | J18: =IFERROR(VLOOKUP($D18,'BASE DE DATOS'!$B:$I,6,0),0) -> ST 1 MZ 19 VILLAMARINA | K18: =IFERROR(VLOOKUP($D18,'BASE DE DATOS'!$B:$I,7,0),0) -> 3215223609 | L18: =IFERROR(VLOOKUP($D18,'BASE DE DATOS'!$B:$I,8,0),0) -> 0 | M18: 120100 | N18: COSTO
A19: 45721 | B19: 48671 | D19: =IFERROR(VLOOKUP($E19,'BASE DE DATOS'!$A:$I,2,0)," ") -> 9009432434 | E19: ='BASE DE DATOS'!$A$153 -> DOLLARCITY | F19: =IFERROR(VLOOKUP($D19,'BASE DE DATOS'!$B:$I,2,0),0) -> 0 | G19: =IFERROR(VLOOKUP($D19,'BASE DE DATOS'!$B:$I,3,0),0) -> 0 | H19: =IFERROR(VLOOKUP($D19,'BASE DE DATOS'!$B:$I,4,0),0) -> 0 | I19: =IFERROR(VLOOKUP($D19,'BASE DE DATOS'!$B:$I,5,0),0) -> 0 | J19: =IFERROR(VLOOKUP($D19,'BASE DE DATOS'!$B:$I,6,0),0) -> AV 3 57 N 30 | K19: =IFERROR(VLOOKUP($D19,'BASE DE DATOS'!$B:$I,7,0),0) -> 0 | L19: =IFERROR(VLOOKUP($D19,'BASE DE DATOS'!$B:$I,8,0),0) -> 0 | M19: 143500 | N19: GASTO
A20: 45721 | B20: 141992 | D20: =IFERROR(VLOOKUP($E20,'BASE DE DATOS'!$A:$I,2,0)," ") -> 901158397 | E20: ='BASE DE DATOS'!$A$113 -> QUESOS Y QUESOS LA CALIDAD SAS | F20: =IFERROR(VLOOKUP($D20,'BASE DE DATOS'!$B:$I,2,0),0) -> 0 | G20: =IFERROR(VLOOKUP($D20,'BASE DE DATOS'!$B:$I,3,0),0) -> 0 | H20: =IFERROR(VLOOKUP($D20,'BASE DE DATOS'!$B:$I,4,0),0) -> 0 | I20: =IFERROR(VLOOKUP($D20,'BASE DE DATOS'!$B:$I,5,0),0) -> 0 | J20: =IFERROR(VLOOKUP($D20,'BASE DE DATOS'!$B:$I,6,0),0) -> CR 17 33 D 36 | K20: =IFERROR(VLOOKUP($D20,'BASE DE DATOS'!$B:$I,7,0),0) -> 3108368823 | L20: =IFERROR(VLOOKUP($D20,'BASE DE DATOS'!$B:$I,8,0),0) -> 0 | M20: 408000 | N20: COSTO
A21: 45723 | B21: 63279 | D21: =IFERROR(VLOOKUP($E21,'BASE DE DATOS'!$A:$I,2,0)," ") -> 66931449 | E21: ='BASE DE DATOS'!$A$112 -> QUESERA Y SALSAMENTARIA LA MAXIMA | F21: =IFERROR(VLOOKUP($D21,'BASE DE DATOS'!$B:$I,2,0),0) -> NO TIENE | G21: =IFERROR(VLOOKUP($D21,'BASE DE DATOS'!$B:$I,3,0),0) -> NO TIENE | H21: =IFERROR(VLOOKUP($D21,'BASE DE DATOS'!$B:$I,4,0),0) -> NO TIENE | I21: =IFERROR(VLOOKUP($D21,'BASE DE DATOS'!$B:$I,5,0),0) -> NO TIENE | J21: =IFERROR(VLOOKUP($D21,'BASE DE DATOS'!$B:$I,6,0),0) -> CR 12 6 33 | K21: =IFERROR(VLOOKUP($D21,'BASE DE DATOS'!$B:$I,7,0),0) -> 2672346 | L21: =IFERROR(VLOOKUP($D21,'BASE DE DATOS'!$B:$I,8,0),0) -> NO TIENE | M21: 253700 | N21: GASTO
A22: 45722 | B22: 13053 | D22: =IFERROR(VLOOKUP($E22,'BASE DE DATOS'!$A:$I,2,0)," ") -> 66886718 | E22: ='BASE DE DATOS'!$A$107 -> PAPELERIA JUVENIL | F22: =IFERROR(VLOOKUP($D22,'BASE DE DATOS'!$B:$I,2,0),0) -> MARIA | G22: =IFERROR(VLOOKUP($D22,'BASE DE DATOS'!$B:$I,3,0),0) -> ISABEL | H22: =IFERROR(VLOOKUP($D22,'BASE DE DATOS'!$B:$I,4,0),0) -> GIRON | I22: =IFERROR(VLOOKUP($D22,'BASE DE DATOS'!$B:$I,5,0),0) -> CERON | J22: =IFERROR(VLOOKUP($D22,'BASE DE DATOS'!$B:$I,6,0),0) -> CL 6 9 52 | K22: =IFERROR(VLOOKUP($D22,'BASE DE DATOS'!$B:$I,7,0),0) -> 2673706 | L22: =IFERROR(VLOOKUP($D22,'BASE DE DATOS'!$B:$I,8,0),0) -> papeleriajuvenil@gmail.com | M22: 10600 | N22: GASTO
A23: 45723 | B23: 0 | D23: =IFERROR(VLOOKUP($E23,'BASE DE DATOS'!$A:$I,2,0)," ") -> 66931449 | E23: QUESERA Y SALSAMENTARIA LA MAXIMA | F23: =IFERROR(VLOOKUP($D23,'BASE DE DATOS'!$B:$I,2,0),0) -> NO TIENE | G23: =IFERROR(VLOOKUP($D23,'BASE DE DATOS'!$B:$I,3,0),0) -> NO TIENE | H23: =IFERROR(VLOOKUP($D23,'BASE DE DATOS'!$B:$I,4,0),0) -> NO TIENE | I23: =IFERROR(VLOOKUP($D23,'BASE DE DATOS'!$B:$I,5,0),0) -> NO TIENE | J23: =IFERROR(VLOOKUP($D23,'BASE DE DATOS'!$B:$I,6,0),0) -> CR 12 6 33 | K23: =IFERROR(VLOOKUP($D23,'BASE DE DATOS'!$B:$I,7,0),0) -> 2672346 | L23: =IFERROR(VLOOKUP($D23,'BASE DE DATOS'!$B:$I,8,0),0) -> NO TIENE | M23: 55000 | N23: GASTO
A24: 45723 | B24: 13099 | D24: =IFERROR(VLOOKUP($E24,'BASE DE DATOS'!$A:$I,2,0)," ") -> 66886718 | E24: PAPELERIA JUVENIL | F24: =IFERROR(VLOOKUP($D24,'BASE DE DATOS'!$B:$I,2,0),0) -> MARIA | G24: =IFERROR(VLOOKUP($D24,'BASE DE DATOS'!$B:$I,3,0),0) -> ISABEL | H24: =IFERROR(VLOOKUP($D24,'BASE DE DATOS'!$B:$I,4,0),0) -> GIRON | I24: =IFERROR(VLOOKUP($D24,'BASE DE DATOS'!$B:$I,5,0),0) -> CERON | J24: =IFERROR(VLOOKUP($D24,'BASE DE DATOS'!$B:$I,6,0),0) -> CL 6 9 52 | K24: =IFERROR(VLOOKUP($D24,'BASE DE DATOS'!$B:$I,7,0),0) -> 2673706 | L24: =IFERROR(VLOOKUP($D24,'BASE DE DATOS'!$B:$I,8,0),0) -> papeleriajuvenil@gmail.com | M24: 12000 | N24: GASTO
A25: 45722 | B25: 0 | D25: =IFERROR(VLOOKUP($E25,'BASE DE DATOS'!$A:$I,2,0)," ") -> 0 | E25: ='BASE DE DATOS'!$A$8 -> BOLSAS PLASTICAS | F25: =IFERROR(VLOOKUP($D25,'BASE DE DATOS'!$B:$I,2,0),0) -> 0 | G25: =IFERROR(VLOOKUP($D25,'BASE DE DATOS'!$B:$I,3,0),0) -> 0 | H25: =IFERROR(VLOOKUP($D25,'BASE DE DATOS'!$B:$I,4,0),0) -> 0 | I25: =IFERROR(VLOOKUP($D25,'BASE DE DATOS'!$B:$I,5,0),0) -> 0 | J25: =IFERROR(VLOOKUP($D25,'BASE DE DATOS'!$B:$I,6,0),0) -> 0 | K25: =IFERROR(VLOOKUP($D25,'BASE DE DATOS'!$B:$I,7,0),0) -> 0 | L25: =IFERROR(VLOOKUP($D25,'BASE DE DATOS'!$B:$I,8,0),0) -> 0 | M25: 30000 | N25: GASTO
A26: 45722 | B26: 0 | D26: =IFERROR(VLOOKUP($E26,'BASE DE DATOS'!$A:$I,2,0)," ") -> 66929745 | E26: POLLOS EL SABOR | F26: =IFERROR(VLOOKUP($D26,'BASE DE DATOS'!$B:$I,2,0),0) -> MARTHA | G26: =IFERROR(VLOOKUP($D26,'BASE DE DATOS'!$B:$I,3,0),0) -> 0 | H26: =IFERROR(VLOOKUP($D26,'BASE DE DATOS'!$B:$I,4,0),0) -> 0 | I26: =IFERROR(VLOOKUP($D26,'BASE DE DATOS'!$B:$I,5,0),0) -> 0 | J26: =IFERROR(VLOOKUP($D26,'BASE DE DATOS'!$B:$I,6,0),0) -> CL 8 12 10 | K26: =IFERROR(VLOOKUP($D26,'BASE DE DATOS'!$B:$I,7,0),0) -> 3017199935 | L26: =IFERROR(VLOOKUP($D26,'BASE DE DATOS'!$B:$I,8,0),0) -> 0 | M26: 748000 | N26: COSTO
A27: 45723 | B27: 4258 | D27: =IFERROR(VLOOKUP($E27,'BASE DE DATOS'!$A:$I,2,0)," ") -> 66929745 | E27: POLLOS EL SABOR | F27: =IFERROR(VLOOKUP($D27,'BASE DE DATOS'!$B:$I,2,0),0) -> MARTHA | G27: =IFERROR(VLOOKUP($D27,'BASE DE DATOS'!$B:$I,3,0),0) -> 0 | H27: =IFERROR(VLOOKUP($D27,'BASE DE DATOS'!$B:$I,4,0),0) -> 0 | I27: =IFERROR(VLOOKUP($D27,'BASE DE DATOS'!$B:$I,5,0),0) -> 0 | J27: =IFERROR(VLOOKUP($D27,'BASE DE DATOS'!$B:$I,6,0),0) -> CL 8 12 10 | K27: =IFERROR(VLOOKUP($D27,'BASE DE DATOS'!$B:$I,7,0),0) -> 3017199935 | L27: =IFERROR(VLOOKUP($D27,'BASE DE DATOS'!$B:$I,8,0),0) -> 0 | M27: 494550 | N27: COSTO
A28: 45724 | B28: 0 | D28: =IFERROR(VLOOKUP($E28,'BASE DE DATOS'!$A:$I,2,0)," ") -> 66931449 | E28: QUESERA Y SALSAMENTARIA LA MAXIMA | F28: =IFERROR(VLOOKUP($D28,'BASE DE DATOS'!$B:$I,2,0),0) -> NO TIENE | G28: =IFERROR(VLOOKUP($D28,'BASE DE DATOS'!$B:$I,3,0),0) -> NO TIENE | H28: =IFERROR(VLOOKUP($D28,'BASE DE DATOS'!$B:$I,4,0),0) -> NO TIENE | I28: =IFERROR(VLOOKUP($D28,'BASE DE DATOS'!$B:$I,5,0),0) -> NO TIENE | J28: =IFERROR(VLOOKUP($D28,'BASE DE DATOS'!$B:$I,6,0),0) -> CR 12 6 33 | K28: =IFERROR(VLOOKUP($D28,'BASE DE DATOS'!$B:$I,7,0),0) -> 2672346 | L28: =IFERROR(VLOOKUP($D28,'BASE DE DATOS'!$B:$I,8,0),0) -> NO TIENE | M28: 35000 | N28: GASTO
A29: 45724 | B29: 0 | D29: =IFERROR(VLOOKUP($E29,'BASE DE DATOS'!$A:$I,2,0)," ") -> 0 | E29: gastos varios caja/ descuadres | F29: =IFERROR(VLOOKUP($D29,'BASE DE DATOS'!$B:$I,2,0),0) -> 0 | G29: =IFERROR(VLOOKUP($D29,'BASE DE DATOS'!$B:$I,3,0),0) -> 0 | H29: =IFERROR(VLOOKUP($D29,'BASE DE DATOS'!$B:$I,4,0),0) -> 0 | I29: =IFERROR(VLOOKUP($D29,'BASE DE DATOS'!$B:$I,5,0),0) -> 0 | J29: =IFERROR(VLOOKUP($D29,'BASE DE DATOS'!$B:$I,6,0),0) -> 0 | K29: =IFERROR(VLOOKUP($D29,'BASE DE DATOS'!$B:$I,7,0),0) -> 0 | L29: =IFERROR(VLOOKUP($D29,'BASE DE DATOS'!$B:$I,8,0),0) -> 0 | M29: 73000 | N29: GASTO
A30: 45724 | B30: 0 | D30: =IFERROR(VLOOKUP($E30,'BASE DE DATOS'!$A:$I,2,0)," ") -> 0 | E30: gastos varios caja/ descuadres | F30: =IFERROR(VLOOKUP($D30,'BASE DE DATOS'!$B:$I,2,0),0) -> 0 | G30: =IFERROR(VLOOKUP($D30,'BASE DE DATOS'!$B:$I,3,0),0) -> 0 | H30: =IFERROR(VLOOKUP($D30,'BASE DE DATOS'!$B:$I,4,0),0) -> 0 | I30: =IFERROR(VLOOKUP($D30,'BASE DE DATOS'!$B:$I,5,0),0) -> 0 | J30: =IFERROR(VLOOKUP($D30,'BASE DE DATOS'!$B:$I,6,0),0) -> 0 | K30: =IFERROR(VLOOKUP($D30,'BASE DE DATOS'!$B:$I,7,0),0) -> 0 | L30: =IFERROR(VLOOKUP($D30,'BASE DE DATOS'!$B:$I,8,0),0) -> 0 | M30: 147000 | N30: GASTO
A31: 45724 | B31: 5010 | D31: =IFERROR(VLOOKUP($E31,'BASE DE DATOS'!$A:$I,2,0)," ") -> 9017363446 | E31: ='BASE DE DATOS'!$A$141 -> DISTRIBUIDORA ZADAY SAS | F31: =IFERROR(VLOOKUP($D31,'BASE DE DATOS'!$B:$I,2,0),0) -> JORGE | G31: =IFERROR(VLOOKUP($D31,'BASE DE DATOS'!$B:$I,3,0),0) -> 0 | H31: =IFERROR(VLOOKUP($D31,'BASE DE DATOS'!$B:$I,4,0),0) -> MOSQUERA | I31: =IFERROR(VLOOKUP($D31,'BASE DE DATOS'!$B:$I,5,0),0) -> 0 | J31: =IFERROR(VLOOKUP($D31,'BASE DE DATOS'!$B:$I,6,0),0) -> MANZANA T CASA 17 MARIA 2 | K31: =IFERROR(VLOOKUP($D31,'BASE DE DATOS'!$B:$I,7,0),0) -> 3017939209 | L31: =IFERROR(VLOOKUP($D31,'BASE DE DATOS'!$B:$I,8,0),0) -> reporte@seitem.com | M31: 79200 | N31: COSTO
A32: 45723 | B32: 697105 | D32: =IFERROR(VLOOKUP($E32,'BASE DE DATOS'!$A:$I,2,0)," ") -> 890500726 | E32: ='BASE DE DATOS'!$A$102 -> NORTESANTANDEREANA DE GAS SA ESP | F32: =IFERROR(VLOOKUP($D32,'BASE DE DATOS'!$B:$I,2,0),0) -> NO TIENE | G32: =IFERROR(VLOOKUP($D32,'BASE DE DATOS'!$B:$I,3,0),0) -> NO TIENE | H32: =IFERROR(VLOOKUP($D32,'BASE DE DATOS'!$B:$I,4,0),0) -> NO TIENE | I32: =IFERROR(VLOOKUP($D32,'BASE DE DATOS'!$B:$I,5,0),0) -> NO TIENE | J32: =IFERROR(VLOOKUP($D32,'BASE DE DATOS'!$B:$I,6,0),0) -> 0 | K32: =IFERROR(VLOOKUP($D32,'BASE DE DATOS'!$B:$I,7,0),0) -> 3208899901 | L32: =IFERROR(VLOOKUP($D32,'BASE DE DATOS'!$B:$I,8,0),0) -> 0 | M32: 420000 | N32: SERVICIOS
A33: 45724 | B33: 0 | D33: =IFERROR(VLOOKUP($E33,'BASE DE DATOS'!$A:$I,2,0)," ") -> 901473419 | E33: ='BASE DE DATOS'!$A$40 -> DISTRIBUCIONES JACOTA ZOMAC SAS | F33: =IFERROR(VLOOKUP($D33,'BASE DE DATOS'!$B:$I,2,0),0) -> 0 | G33: =IFERROR(VLOOKUP($D33,'BASE DE DATOS'!$B:$I,3,0),0) -> 0 | H33: =IFERROR(VLOOKUP($D33,'BASE DE DATOS'!$B:$I,4,0),0) -> 0 | I33: =IFERROR(VLOOKUP($D33,'BASE DE DATOS'!$B:$I,5,0),0) -> 0 | J33: =IFERROR(VLOOKUP($D33,'BASE DE DATOS'!$B:$I,6,0),0) -> CR 10 5 32 | K33: =IFERROR(VLOOKUP($D33,'BASE DE DATOS'!$B:$I,7,0),0) -> 3147560646 | L33: =IFERROR(VLOOKUP($D33,'BASE DE DATOS'!$B:$I,8,0),0) -> jacota.distribuciones@outlook.com | M33: 501900 | N33: COSTO
A34: 45717 | B34: 6170 | D34: =IFERROR(VLOOKUP($E34,'BASE DE DATOS'!$A:$I,2,0)," ") -> 66660257 | E34: ='BASE DE DATOS'!$A$38 -> DISOIL | F34: =IFERROR(VLOOKUP($D34,'BASE DE DATOS'!$B:$I,2,0),0) -> 0 | G34: =IFERROR(VLOOKUP($D34,'BASE DE DATOS'!$B:$I,3,0),0) -> 0 | H34: =IFERROR(VLOOKUP($D34,'BASE DE DATOS'!$B:$I,4,0),0) -> 0 | I34: =IFERROR(VLOOKUP($D34,'BASE DE DATOS'!$B:$I,5,0),0) -> 0 | J34: =IFERROR(VLOOKUP($D34,'BASE DE DATOS'!$B:$I,6,0),0) -> CL 21 31 37 | K34: =IFERROR(VLOOKUP($D34,'BASE DE DATOS'!$B:$I,7,0),0) -> 3005547057 | L34: =IFERROR(VLOOKUP($D34,'BASE DE DATOS'!$B:$I,8,0),0) -> 0 | M34: 292000 | N34: SERVICIOS
A35: 45724 | B35: 6219 | D35: =IFERROR(VLOOKUP($E35,'BASE DE DATOS'!$A:$I,2,0)," ") -> 66660257 | E35: DISOIL | F35: =IFERROR(VLOOKUP($D35,'BASE DE DATOS'!$B:$I,2,0),0) -> 0 | G35: =IFERROR(VLOOKUP($D35,'BASE DE DATOS'!$B:$I,3,0),0) -> 0 | H35: =IFERROR(VLOOKUP($D35,'BASE DE DATOS'!$B:$I,4,0),0) -> 0 | I35: =IFERROR(VLOOKUP($D35,'BASE DE DATOS'!$B:$I,5,0),0) -> 0 | J35: =IFERROR(VLOOKUP($D35,'BASE DE DATOS'!$B:$I,6,0),0) -> CL 21 31 37 | K35: =IFERROR(VLOOKUP($D35,'BASE DE DATOS'!$B:$I,7,0),0) -> 3005547057 | L35: =IFERROR(VLOOKUP($D35,'BASE DE DATOS'!$B:$I,8,0),0) -> 0 | M35: 292000 | N35: SERVICIOS
A36: 45725 | B36: 462469 | D36: =IFERROR(VLOOKUP($E36,'BASE DE DATOS'!$A:$I,2,0)," ") -> 815002459 | E36: ='BASE DE DATOS'!$A$94 -> MERCAPAVA SA | F36: =IFERROR(VLOOKUP($D36,'BASE DE DATOS'!$B:$I,2,0),0) -> NO TIENE | G36: =IFERROR(VLOOKUP($D36,'BASE DE DATOS'!$B:$I,3,0),0) -> NO TIENE | H36: =IFERROR(VLOOKUP($D36,'BASE DE DATOS'!$B:$I,4,0),0) -> NO TIENE | I36: =IFERROR(VLOOKUP($D36,'BASE DE DATOS'!$B:$I,5,0),0) -> NO TIENE | J36: =IFERROR(VLOOKUP($D36,'BASE DE DATOS'!$B:$I,6,0),0) -> CL 7 12 03 | K36: =IFERROR(VLOOKUP($D36,'BASE DE DATOS'!$B:$I,7,0),0) -> 3136831049 | L36: =IFERROR(VLOOKUP($D36,'BASE DE DATOS'!$B:$I,8,0),0) -> 0 | M36: 36820 | N36: GASTO
A37: 45725 | B37: 84 | D37: =IFERROR(VLOOKUP($E37,'BASE DE DATOS'!$A:$I,2,0)," ") -> 1112230545 | E37: ='BASE DE DATOS'!$A$115 -> salsamentaria | F37: =IFERROR(VLOOKUP($D37,'BASE DE DATOS'!$B:$I,2,0),0) -> 0 | G37: =IFERROR(VLOOKUP($D37,'BASE DE DATOS'!$B:$I,3,0),0) -> 0 | H37: =IFERROR(VLOOKUP($D37,'BASE DE DATOS'!$B:$I,4,0),0) -> 0 | I37: =IFERROR(VLOOKUP($D37,'BASE DE DATOS'!$B:$I,5,0),0) -> 0 | J37: =IFERROR(VLOOKUP($D37,'BASE DE DATOS'!$B:$I,6,0),0) -> 0 | K37: =IFERROR(VLOOKUP($D37,'BASE DE DATOS'!$B:$I,7,0),0) -> 3107292255 | L37: =IFERROR(VLOOKUP($D37,'BASE DE DATOS'!$B:$I,8,0),0) -> NO TIENE | M37: 42800 | N37: GASTO
A38: 45725 | B38: 0 | D38: =IFERROR(VLOOKUP($E38,'BASE DE DATOS'!$A:$I,2,0)," ") -> 0 | E38: =$E$10 -> MERCAFRUVER LA ECONOMIA demi pradera | F38: =IFERROR(VLOOKUP($D38,'BASE DE DATOS'!$B:$I,2,0),0) -> 0 | G38: =IFERROR(VLOOKUP($D38,'BASE DE DATOS'!$B:$I,3,0),0) -> 0 | H38: =IFERROR(VLOOKUP($D38,'BASE DE DATOS'!$B:$I,4,0),0) -> 0 | I38: =IFERROR(VLOOKUP($D38,'BASE DE DATOS'!$B:$I,5,0),0) -> 0 | J38: =IFERROR(VLOOKUP($D38,'BASE DE DATOS'!$B:$I,6,0),0) -> 0 | K38: =IFERROR(VLOOKUP($D38,'BASE DE DATOS'!$B:$I,7,0),0) -> 0 | L38: =IFERROR(VLOOKUP($D38,'BASE DE DATOS'!$B:$I,8,0),0) -> 0 | M38: 168000 | N38: COSTO
A39: 45724 | B39: 0 | D39: =IFERROR(VLOOKUP($E39,'BASE DE DATOS'!$A:$I,2,0)," ") -> 0 | E39: gastos varios caja/ descuadres | F39: =IFERROR(VLOOKUP($D39,'BASE DE DATOS'!$B:$I,2,0),0) -> 0 | G39: =IFERROR(VLOOKUP($D39,'BASE DE DATOS'!$B:$I,3,0),0) -> 0 | H39: =IFERROR(VLOOKUP($D39,'BASE DE DATOS'!$B:$I,4,0),0) -> 0 | I39: =IFERROR(VLOOKUP($D39,'BASE DE DATOS'!$B:$I,5,0),0) -> 0 | J39: =IFERROR(VLOOKUP($D39,'BASE DE DATOS'!$B:$I,6,0),0) -> 0 | K39: =IFERROR(VLOOKUP($D39,'BASE DE DATOS'!$B:$I,7,0),0) -> 0 | L39: =IFERROR(VLOOKUP($D39,'BASE DE DATOS'!$B:$I,8,0),0) -> 0 | M39: 97000 | N39: GASTO
A40: 45724 | B40: 0 | D40: =IFERROR(VLOOKUP($E40,'BASE DE DATOS'!$A:$I,2,0)," ") -> 0 | E40: ='BASE DE DATOS'!$A$174 -> LECHUGA | F40: =IFERROR(VLOOKUP($D40,'BASE DE DATOS'!$B:$I,2,0),0) -> 0 | G40: =IFERROR(VLOOKUP($D40,'BASE DE DATOS'!$B:$I,3,0),0) -> 0 | H40: =IFERROR(VLOOKUP($D40,'BASE DE DATOS'!$B:$I,4,0),0) -> 0 | I40: =IFERROR(VLOOKUP($D40,'BASE DE DATOS'!$B:$I,5,0),0) -> 0 | J40: =IFERROR(VLOOKUP($D40,'BASE DE DATOS'!$B:$I,6,0),0) -> 0 | K40: =IFERROR(VLOOKUP($D40,'BASE DE DATOS'!$B:$I,7,0),0) -> 0 | L40: =IFERROR(VLOOKUP($D40,'BASE DE DATOS'!$B:$I,8,0),0) -> 0 | M40: 15400 | N40: COSTO
...

Sheet INGRESOS
A1: INGRESOS MARZO 2025
A3: FECHA | B3: CAJA | C3: BANCOS | D3: TARJETA CR
A4: 45717 | B4: 3797500 | C4: 1069500 | D4: 117900
A5: 45718 | B5: 3452500 | C5: 411000 | D5: 58150
A6: 45719
A7: 45720
A8: 45721 | B8: 664500 | C8: 128500 | D8: 12350
A9: 45722 | B9: 1468500 | C9: 246000 | D9: 0
A10: 45723 | B10: 1653500 | C10: 504000 | D10: 152400
A11: 45724 | B11: 4781000 | C11: 1005500 | D11: 111200
A12: 45725 | B12: 3348000 | C12: 945500 | D12: 118900
A13: 45726
A14: 45727
A15: 45728 | B15: 952500 | C15: 246500 | D15: 62800
A16: 45729 | B16: 666000 | C16: 271500 | D16: 19550
A17: 45730 | B17: 1316000 | C17: 613500 | D17: 97300
A18: 45731 | B18: 3208500 | C18: 554500 | D18: 181200
A19: 45732 | B19: 2513000 | C19: 942500 | D19: 96000
A20: 45733
A21: 45734
A22: 45735 | B22: 1110000 | C22: 497000 | D22: 37050
A23: 45736 | B23: 976000 | C23: 386000 | D23: 90100
A24: 45737 | B24: 1315600 | C24: 561000 | D24: 53450
A25: 45738 | B25: 3812500 | C25: 597000 | D25: 132800
A26: 45739 | B26: 3157000 | C26: 447500 | D26: 146750
A27: 45740 | B27: 2350000 | C27: 868500 | D27: 155000
A28: 45741
A29: 45742
A30: 45743 | B30: 1124000 | C30: 224500 | D30: 0
A31: 45744 | B31: 2299800 | C31: 1102500 | D31: 157050
A32: 45745 | B32: 6007200 | C32: 1209400 | D32: 400550
A33: 45746 | B33: 4439900 | C33: 1762200 | D33: 155200
A34: 45747 | B34: 1579300 | C34: 665800 | D34: 92350
A36: TOTAL | B36: =SUM(B4:B34) -> 55992800 | C36: =SUM(C4:C34) -> 15259900 | D36: =SUM(D4:D34) -> 2448050 | F36: =SUM(B36:D36) -> 73700750

Sheet BASE DE DATOS
A1: RAZON SOCIAL | B1: NIT | C1: PRIMER NOMBRE | D1: SEGUNDO NOMBRE | E1: PRIMER APELLIDO | F1: SEGUNDOAPELLIDO | G1: DIRECCION | H1: TELEFONO | I1: Correo | J1: TIPO
A2: AGENCIA LUPA SAS | B2: 901086443 | G2: CR 31 9C70 | H2: 3165288931 | J2: COSTO
A3: aguacates | J3: COSTO
A4: =CONCATENATE(C4," ",D4," ",E4," ",F4) -> ALBA NELLY VALDES CUERO | B4: 66885892 | C4: ALBA | D4: NELLY | E4: VALDES | F4: CUERO | G4: CL 10 17 25 | H4: 3225908464 | J4: EMPLEADO
A5: APORTES EN LINEA | B5: 900147238 | G5: CR 14ª No. 101-47 | H5: 4853939 | J5: SEG SOCIAL
A6: BARRA ESTANCO EL BARRIL DE LA SEXTA | B6: 29705164 | C6: DIANA | D6: MARIA | E6: ARIAS | F6: ECHAVARRIA | G6: CL 6 11 03 | H6: 3163471484 | J6: COSTO
A7: BIMBO DE COLOMBIA SA | B7: 830002366 | C7: NO TIENE | D7: NO TIENE | E7: NO TIENE | F7: NO TIENE | G7: KM 12 AUTOPISTA MEDELLIN | J7: COSTO
A8: BOLSAS PLASTICAS | J8: GASTO
A9: =CONCATENATE(C9," ",D9," ",E9," ",F9) -> BREINER RESTREPO | C9: BREINER | E9: RESTREPO | J9: EMPLEADO
A10: BRENDA GOMEZ | B10: 1112219602 | C10: BRENDA | E10: GOMEZ | G10: CR 10 CASA 24 | H10: 3116075631 | J10: EMPLEADO
A11: CAJAS MORSA | J11: COSTO
A12: =CONCATENATE(C12," ",D12," ",E12," ",F12) -> CAMILA GOMEZ | B12: 1113696548 | C12: CAMILA | E12: GOMEZ | G12: CL 4 3 27 | H12: 3113807982 | J12: EMPLEADO
A13: CELSIA COLOMBIA SA ESP | B13: 800249860 | C13: NO TIENE | D13: NO TIENE | E13: NO TIENE | F13: NO TIENE | G13: CL 15 29 30 | H13: 3210000 | I13: servicioalcliente@celsia.com | J13: SERVICIOS
A14: CENTRO DIAGNOSTICO AUTOMOTOR PARAISO SAS | B14: 900560653 | G14: TV 30 1 271 | H14: 2755717 | I14: cdaparaisocsa@gmail.com | J14: GASTO
A15: CES RED LOGISTICA SAS | B15: 901265547 | G15: CL 77 16A 15 | H15: 3163927576 | I15: notificaciones@cesred.com | J15: GASTO
A16: CESAR AUGUSTO SASTOQUE | B16: 1112223387 | C16: CESAR | D16: AUGUSTO | E16: SASTOQUE | G16: CL 6 12 84 | H16: 3188276966 | J16: EMPLEADO
A17: CINDY JOHANA AGUILAR | B17: 1193134535 | C17: CINDY | D17: JOHANA | E17: AGUILAR | G17: MZ 33 CASA 15 | H17: 3235481899 | J17: EMPLEADO
A18: COCO LOKO PIÑATERIA Y JUGUETERIA | B18: 29707452 | J18: GASTO
A19: COLANTA | B19: 94303413 | C19: GUSTAVO | D19: ADOLFO | E19: CAMPO | F19: TORRES | G19: CL 6 13 04 | H19: 3136595942 | J19: COSTO
A20: COLOMBIA TELECOMUNICACIONES SA | B20: 830122566 | J20: SERVICIOS
A21: COMCEL SA | B21: 800153993 | C21: NO TIENE | D21: NO TIENE | E21: NO TIENE | F21: NO TIENE | J21: SERVICIOS
A22: COMERCIALIZADORA GARCIA Y ASOCIADOS | B22: 901249410 | G22: CL 27 25 26 | H22: 2856473 | J22: COSTO
A23: COMERCIALIZADORA H&F | B23: 901344319 | G23: CR 11 7 52 | J23: COSTO
A24: COMERCIALIZADORA MARDEN LTDA | B24: 800004599 | G24: MARDEN BOSQUE | J24: GASTO
A25: COMERCIALIZADORA SASTOQUE | H25: 3178278606 | J25: COSTO
A26: CRISTALERIA EL REMATE DE LA 11 | B26: 10085753 | G26: CR 11 7 08 | H26: 3163314926 | J26: GASTO
A27: =CONCATENATE(C27," ",D27," ",E27," ",F27) -> CRISTIAN GALLEGO | C27: CRISTIAN | E27: GALLEGO | J27: EMPLEADO
A28: CRISTIAN ANDRES MOSQUERA CIRO | B28: 1112224034 | C28: CRISTIAN | D28: ANDRES | E28: MOSQUERA | F28: CIRO | G28: CL 2B TV 13 33 | H28: 3104657035 | J28: EMPLEADO
A29: CRISTIAN YAHIR GUERRERO GIRON | B29: 1006218066 | C29: CRISTIAN | D29: YAHIR | E29: GUERRERO | F29: GIRON | G29: CL 10 14 63 | H29: 3215272745 | J29: EMPLEADO
A30: CRISTINA ALEJANDRA SINISTERRA PALOMINO | B30: 1006035547 | C30: CRISTINA | D30: ALEJANDRA | E30: SINISTERRA | F30: PALOMINO | G30: CR 13 1B 38 | H30: 3122529315 | J30: EMPLEADO
A31: CUATRO ESQUINAS DON HERNAN | B31: 12911666 | C31: FREDY | D31: HERNAN | E31: CABEZAS | G31: CR 15 CL 9 CASA 28 | H31: 3216713381 | J31: PATROCINIO
A32: D1 SAS | B32: 900276962 | H32: 18000120201 | J32: GASTO
A33: =CONCATENATE(C33," ",D33," ",E33," ",F33) -> DANEISY GARCIA | B33: 1003152815 | C33: DANEISY | E33: GARCIA | G33: CL 10 14 48 | H33: 3103083893 | J33: EMPLEADO
A34: DANNA SOALRTE ROJAS | B34: 1114621431 | C34: DANNA | E34: SOALRTE | F34: ROJAS | G34: CR 3 5 38 | H34: 3027634803 | J34: EMPLEADO
A35: DARLING MARIANA ROJAS GONZALES | B35: 1114621502 | C35: DARLING | D35: MARIANA | E35: ROJAS | F35: GONZALES | G35: MZ C CASA 21 LA LORENA | H35: 3217975473 | J35: EMPLEADO
A36: DARSALUD DROGUERIA | B36: 835000779 | G36: CR 8 10 08 | H36: 2757817 | J36: GASTO
A37: DEPOSITO PRINCIPAL DE DROGAS LTDA | B37: 860514592 | J37: GASTO
A38: DISOIL | B38: 66660257 | G38: CL 21 31 37 | H38: 3005547057 | J38: COSTO
A39: DISOIL | B39: 66660257 | G39: DG 29A T7A 155 | H39: 3005547057 | J39: COSTO
A40: DISTRIBUCIONES JACOTA ZOMAC SAS | B40: 901473419 | G40: CR 10 5 32 | H40: 3147560646 | I40: jacota.distribuciones@outlook.com | J40: COSTO
...
