Workbook
Name Lt_Empleados: [1]Datos!$P$12:$P$26

Sheet Asistencia
S1: 1RA QUINCENA | AI1: 2DA QUINCENA
B2: NOMBRE | C2: CEDULA | D2: 1 | E2: 2 | F2: 3 | G2: 4 | H2: 5 | I2: 6 | J2: 7 | K2: 8 | L2: 9 | M2: 10 | N2: 11 | O2: 12 | P2: 13 | Q2: 14 | R2: 15 | S2: TOTAL DIAS | T2: 16 | U2: 17 | V2: 18 | W2: 19 | X2: 20 | Y2: 21 | Z2: 22 | AA2: 23 | AB2: 24 | AC2: 25 | AD2: 26 | AE2: 27 | AF2: 28 | AG2: 29 | AH2: 30 | AI2: TOTAL DIAS
A3: 1 | B3: ANDRES FELIPE CHAUX TASCON | C3: 1107514369 | S3: =SUM(D3:R3) -> 0 | V3: 1 | W3: 1 | X3: 1 | Y3: 1 | Z3: 1 | AA3: 1 | AB3: 1 | AC3: 1 | AD3: 1 | AE3: 1 | AF3: 1 | AG3: 1 | AH3: 1 | AI3: =SUM(T3:AH3) -> 13
A4: 2 | B4: JOSE MANUEL OCAMPO VILLADA | C4: 1006216897 | S4: =SUM(D4:R4) -> 0 | V4: 1 | W4: 1 | X4: 1 | Y4: 1 | Z4: 1 | AA4: 1 | AB4: 1 | AC4: 1 | AD4: 1 | AE4: 1 | AF4: 1 | AG4: 1 | AH4: 1 | AI4: =SUM(T4:AH4) -> 13
A5: 3 | B5: KEVIN JOHAN HURTADO CAÑAVERAL | C5: 1086279269 | S5: =SUM(D5:R5) -> 0 | V5: 1 | W5: 1 | X5: 1 | Y5: 1 | Z5: 1 | AA5: 1 | AB5: 1 | AC5: 1 | AD5: 1 | AE5: 1 | AF5: 1 | AG5: 1 | AH5: 1 | AI5: =SUM(T5:AH5) -> 13
A6: 4 | B6: VICTORIA MONTENEGRO MONTAÑO | C6: 1112226821 | S6: =SUM(D6:R6) -> 0 | V6: 1 | W6: 1 | X6: 1 | Y6: 1 | Z6: 1 | AA6: 1 | AB6: 1 | AC6: 1 | AD6: 1 | AE6: 1 | AF6: 1 | AG6: 1 | AH6: 1 | AI6: =SUM(T6:AH6) -> 13
A7: 5 | B7: LEANDRO ANTONIO POPAYAN MELO | C7: 1113676974 | S7: =SUM(D7:R7) -> 0 | V7: 1 | W7: 1 | X7: 1 | Y7: 1 | Z7: 1 | AA7: 1 | AB7: 1 | AC7: 1 | AD7: 1 | AE7: 1 | AF7: 1 | AG7: 1 | AH7: 1 | AI7: =SUM(T7:AH7) -> 13
A8: 6 | B8: CHRISTIAN STIVEN GIRON POSADA | C8: 1114620530 | S8: =SUM(D8:R8) -> 0 | V8: 1 | W8: 1 | X8: 1 | Y8: 1 | Z8: 1 | AA8: 1 | AB8: 1 | AC8: 1 | AD8: 1 | AE8: 1 | AF8: 1 | AG8: 1 | AH8: 1 | AI8: =SUM(T8:AH8) -> 13
B10: DOMINGOS Y FESTIVOS
B11: NO FUE
B12: INCAPACIDAD
B13: PERMISO NO REMUNERADO
B14: CITA MEDICA
B15: VACACIONES

Sheet Desprendible FIJOS
B1: LA MORSA FOODS SAS | G1: LA MORSA FOODS SAS
B2: DESPRENDIBLE DE PAGO | D2: 01-15 FEBRERO 2026 | G2: DESPRENDIBLE DE PAGO | I2: 16-30 FEBRERO 2026
B3: NOMBRE | D3: =+Asistencia!B3 -> ANDRES FELIPE CHAUX TASCON | G3: NOMBRE | I3: =+D3 -> ANDRES FELIPE CHAUX TASCON
B4: CEDULA | D4: 94300332 | G4: CEDULA | I4: =+D4 -> 94300332
B5: VALOR DIA | C5: 58363.5 | D5: DIAS LABORADOS | E5: =+Asistencia!S4 -> 0 | G5: VALOR DIA | H5: 58363.5 | I5: DIAS LABORADOS | J5: =+Asistencia!AI4 -> 13
B6: TOTAL QUINCENA | E6: =+$E$5*$C$5 -> 0 | G6: TOTAL QUINCENA | J6: =+H5*$J$5 -> 758725.5 | L6: DEVENGADO | M6: =+E6+J6 -> 758725.5 | N6: TOTAL DIAS | O6: =+$E$5+$J$5 -> 13
B7: AUXILIO DE TRANSPORTE | E7: =+$E$5*$C$5 -> 0 | G7: AUXILIO DE TRANSPORTE | J7: 0 | L7: AUX TRANSP | M7: =+E7+J7 -> 0
B8: DEDUCCIONES | C8: SALUD | D8: 0.04 | E8: =+E6*$D$8 -> 0 | G8: DEDUCCIONES | H8: SALUD | I8: 0.04 | J8: =+J6*$I$8 -> 30349.02 | L8: DEDUCCION | M8: =+E8+J8+E9+J9 -> 60698.04
C9: PENSIÓN | D9: 0.04 | E9: =+E6*$D$9 -> 0 | H9: PENSIÓN | I9: 0.04 | J9: =+J6*$I$9 -> 30349.02 | L9: INCAPACIDAD
B10: NETO PAGADO | E10: =+E6+E7-E8-E9 -> 0 | G10: NETO PAGADO | J10: =+J6+J7-J8-J9 -> 698027.46 | L10: DESCUENTO
B11: NOVEDADES: | G11: NOVEDADES: | L11: TOTAL MES | M11: =+M6+M7 -> 758725.5
D13: HECTAREAS | I13: HECTAREAS
B15: LA MORSA FOODS SAS | G15: LA MORSA FOODS SAS
B16: DESPRENDIBLE DE PAGO | D16: 01-15 FEBRERO 2026 | G16: DESPRENDIBLE DE PAGO | I16: 16-30 FEBRERO 2026
B17: NOMBRE | D17: =+Asistencia!B4 -> JOSE MANUEL OCAMPO VILLADA | G17: NOMBRE | I17: =+D17 -> JOSE MANUEL OCAMPO VILLADA
B18: CEDULA | D18: 6400848 | G18: CEDULA | I18: =+D18 -> 6400848
B19: VALOR DIA | C19: 58363.5 | D19: DIAS LABORADOS | E19: =+Asistencia!S7 -> 0 | G19: VALOR DIA | H19: 58363.5 | I19: DIAS LABORADOS | J19: =+Asistencia!AI7 -> 13
B20: TOTAL QUINCENA | E20: =+C19*$E$19 -> 0 | G20: TOTAL QUINCENA | J20: =+H19*$J$19 -> 758725.5 | L20: DEVENGADO | M20: =+E20+J20 -> 758725.5 | N20: TOTAL DIAS | O20: =+E19+J19 -> 13
B21: DEDUCCIONES | C21: SALUD | D21: 0.04 | E21: =+E20*$D$21 -> 0 | G21: DEDUCCIONES | H21: SALUD | I21: 0.04 | J21: =+J20*$I$21 -> 30349.02 | L21: DEDUCCION | M21: =+E21+J21+E22+J22 -> 60698.04
C22: PENSIÓN | D22: 0.04 | E22: =+E20*$D$22 -> 0 | H22: PENSIÓN | I22: 0.04 | J22: =+J20*$I$22 -> 30349.02 | L22: INCAPACIDAD
B23: NETO PAGADO | E23: =+E20-E21-E22 -> 0 | G23: NETO PAGADO | J23: =+J20-J21-J22 -> 698027.46 | L23: DESCUENTO
B24: NOVEDADES: | L24: TOTAL MES | M24: =+E23+J23 -> 698027.46
B28: LA MORSA FOODS SAS | G28: LA MORSA FOODS SAS
B29: DESPRENDIBLE DE PAGO | D29: 01-15 FEBRERO 2026 | G29: DESPRENDIBLE DE PAGO | I29: 16-30 FEBRERO 2026
B30: NOMBRE | D30: =+Asistencia!B5 -> KEVIN JOHAN HURTADO CAÑAVERAL | G30: NOMBRE | I30: =+D30 -> KEVIN JOHAN HURTADO CAÑAVERAL
B31: CEDULA | D31: 94300447 | G31: CEDULA | I31: 94300447
B32: VALOR DIA | C32: 58363.5 | D32: DIAS LABORADOS | E32: =+Asistencia!S3 -> 0 | G32: VALOR DIA | H32: 58363.5 | I32: DIAS LABORADOS | J32: =+Asistencia!AI3 -> 13
B33: TOTAL QUINCENA | E33: =+$E$32*$C$32 -> 0 | G33: TOTAL QUINCENA | J33: =+H32*$J$32 -> 758725.5
B34: AUXILIO DE TRANSPORTE | E34: 0 | G34: AUXILIO DE TRANSPORTE | J34: 0
B35: DEDUCCIONES | C35: SALUD | D35: 0.04 | E35: =+E33*$D$35 -> 0 | G35: DEDUCCIONES | H35: SALUD | I35: 0.04 | J35: =+J33*$I$35 -> 30349.02 | L35: DEVENGADO | M35: =+E33+J33 -> 758725.5 | N35: TOTAL DIAS | O35: =+E32+J32 -> 13
C36: PENSIÓN | D36: 0.04 | E36: =+E33*$D$36 -> 0 | H36: PENSIÓN | I36: 0.04 | J36: =+J33*$I$36 -> 30349.02 | L36: AUX TRANSP | M36: =+E34+J34 -> 0
B37: NETO PAGADO | E37: =+E33+E34-E35-E36 -> 0 | G37: NETO PAGADO | J37: =+J33+J34-J35-J36 -> 698027.46 | L37: DEDUCCION | M37: =+E35+J35+E36+J36 -> 60698.04
B38: NOVEDADES: | G38: NOVEDADES: | L38: INCAPACIDAD
L39: DESCUENTO
D40: HECTAREAS | I40: HECTAREAS | L40: TOTAL MES | M40: =+M35+M36 -> 758725.5
B42: LA MORSA FOODS SAS | G42: LA MORSA FOODS SAS
B43: DESPRENDIBLE DE PAGO | D43: 01-15 FEBRERO 2026 | G43: DESPRENDIBLE DE PAGO | I43: 16-30 FEBRERO 2026
B44: NOMBRE | D44: =+Asistencia!B6 -> VICTORIA MONTENEGRO MONTAÑO | G44: NOMBRE | I44: =+D44 -> VICTORIA MONTENEGRO MONTAÑO
B45: CEDULA | D45: 6739243 | G45: CEDULA | I45: =+D45 -> 6739243
B46: VALOR DIA | C46: 58363.5 | D46: DIAS LABORADOS | E46: =+Asistencia!S8 -> 0 | G46: VALOR DIA | H46: 58363.5 | I46: DIAS LABORADOS | J46: =+Asistencia!AI8 -> 13
...

Sheet NOM_FIJOS
B1: FEBRERO - PRIMERA QUINCENA | P1: FEBRERO - SEGUNDA QUINCENA
B3: PLANILLA DE PAGO | P3: PLANILLA DE PAGO
B4: LA MORSA FOODS SAS | P4: LA MORSA FOODS SAS
B5: NIT 902024494-0 | P5: NIT 902024494-0
B6: PERIODO DE PAGO: | C6: FEBRERO DE 2026 | G6: 01 QUINCENA | P6: PERIODO DE PAGO: | Q6: FEBRERO DE 2026 | U6: 02 QUINCENA
B7: NOMBRE EMPLEADO | C7: CEDULA DE CIUDADANIA | D7: DT | E7: DEVENGOS | H7: DEDUCCION | K7: TOTAL DEDUCIDO | L7: NETO PAGADO | P7: NOMBRE EMPLEADO | Q7: CEDULA DE CIUDADANIA | R7: DT | S7: DEVENGOS | V7: DEDUCCION | Y7: TOTAL DEDUCIDO | Z7: NETO PAGADO
E8: SUELDO | F8: AUX TRA | G8: IN/CIDAD | H8: PENSION | I8: SALUD | J8: PRESTAMO | S8: SUELDO | T8: AUX TRA | U8: IN/CIDAD | V8: PENSION | W8: SALUD | X8: PRESTAMO
A9: 1 | B9: =+Asistencia!B3 -> ANDRES FELIPE CHAUX TASCON | C9: =+Asistencia!C3 -> 1107514369 | D9: =+'Desprendible FIJOS'!E32 -> 0 | E9: =+'Desprendible FIJOS'!E33 -> 0 | F9: =+'Desprendible FIJOS'!E34 -> 0 | H9: =(E9+G9)*4% -> 0 | I9: =(E9+G9)*4% -> 0 | K9: =+H9+I9+J9 -> 0 | L9: =+E9+F9+G9-K9 -> 0 | O9: 1 | P9: =+Asistencia!B3 -> ANDRES FELIPE CHAUX TASCON | Q9: =+Asistencia!C3 -> 1107514369 | R9: =+'Desprendible FIJOS'!J32 -> 13 | S9: =+'Desprendible FIJOS'!J33 -> 758725.5 | T9: =+'Desprendible FIJOS'!J34 -> 0 | V9: =(S9+U9)*4% -> 30349.02 | W9: =(S9+U9)*4% -> 30349.02 | X9: 0 | Y9: =+V9+W9+X9 -> 60698.04 | Z9: =+S9+T9+U9-Y9 -> 698027.46
A10: 2 | B10: =+Asistencia!B4 -> JOSE MANUEL OCAMPO VILLADA | C10: =+Asistencia!C4 -> 1006216897 | D10: =+'Desprendible FIJOS'!$E$5 -> 0 | E10: =+'Desprendible FIJOS'!$E$6 -> 0 | F10: =+'Desprendible FIJOS'!E7 -> 0 | H10: =(E10+G10)*4% -> 0 | I10: =(E10+G10)*4% -> 0 | K10: =+H10+I10+J10 -> 0 | L10: =+E10+F10+G10-K10 -> 0 | O10: 2 | P10: =+Asistencia!B4 -> JOSE MANUEL OCAMPO VILLADA | Q10: =+Asistencia!C4 -> 1006216897 | R10: =+'Desprendible FIJOS'!$J$5 -> 13 | S10: =+'Desprendible FIJOS'!$J$6 -> 758725.5 | T10: =+'Desprendible FIJOS'!$J$7 -> 0 | V10: =(S10+U10)*4% -> 30349.02 | W10: =(S10+U10)*4% -> 30349.02 | Y10: =+V10+W10+X10 -> 60698.04 | Z10: =+S10+T10+U10-Y10 -> 698027.46
A11: 3 | B11: =+Asistencia!B5 -> KEVIN JOHAN HURTADO CAÑAVERAL | C11: =+Asistencia!C5 -> 1086279269 | D11: =+'Desprendible FIJOS'!$E$19 -> 0 | E11: =+'Desprendible FIJOS'!$E$20 -> 0 | H11: =(E11+G11)*4% -> 0 | I11: =(E11+G11)*4% -> 0 | K11: =+H11+I11+J11 -> 0 | L11: =+E11+F11+G11-K11 -> 0 | O11: 3 | P11: =+Asistencia!B5 -> KEVIN JOHAN HURTADO CAÑAVERAL | Q11: =+Asistencia!C5 -> 1086279269 | R11: =+'Desprendible FIJOS'!$J$19 -> 13 | S11: =+'Desprendible FIJOS'!$J$20 -> 758725.5 | V11: =(S11+U11)*4% -> 30349.02 | W11: =(S11+U11)*4% -> 30349.02 | Y11: =+V11+W11+X11 -> 60698.04 | Z11: =+S11+T11+U11-Y11 -> 698027.46
A12: 4 | B12: =+Asistencia!B6 -> VICTORIA MONTENEGRO MONTAÑO | C12: =+Asistencia!C6 -> 1112226821 | D12: =+'Desprendible FIJOS'!$E$46 -> 0 | E12: =+'Desprendible FIJOS'!$E$47 -> 0 | F12: =+'Desprendible FIJOS'!$E$48 -> 0 | H12: =(E12+G12)*4% -> 0 | I12: =(E12+G12)*4% -> 0 | K12: =+H12+I12+J12 -> 0 | L12: =+E12+F12+G12-K12 -> 0 | O12: 4 | P12: =+Asistencia!B6 -> VICTORIA MONTENEGRO MONTAÑO | Q12: =+Asistencia!C6 -> 1112226821 | R12: =+'Desprendible FIJOS'!$J$46 -> 13 | S12: =+'Desprendible FIJOS'!$J$47 -> 758725.5 | T12: =+'Desprendible FIJOS'!$J$48 -> 0 | V12: =(S12+U12)*4% -> 30349.02 | W12: =(S12+U12)*4% -> 30349.02 | Y12: =+V12+W12+X12 -> 60698.04 | Z12: =+S12+T12+U12-Y12 -> 698027.46
A13: 5 | B13: =+Asistencia!B7 -> LEANDRO ANTONIO POPAYAN MELO | C13: =+Asistencia!C7 -> 1113676974 | D13: =+'Desprendible FIJOS'!E60 -> 0 | E13: =+'Desprendible FIJOS'!E61 -> 0 | F13: =+'Desprendible FIJOS'!E62 -> 0 | H13: =(E13+G13)*4% -> 0 | I13: =(E13+G13)*4% -> 0 | K13: =+H13+I13+J13 -> 0 | L13: =+E13+F13+G13-K13 -> 0 | O13: 5 | P13: =+Asistencia!B7 -> LEANDRO ANTONIO POPAYAN MELO | Q13: =+Asistencia!C7 -> 1113676974 | R13: =+'Desprendible FIJOS'!$J$60 -> 13 | S13: =+'Desprendible FIJOS'!$J$61 -> 758725.5 | T13: =+'Desprendible FIJOS'!J62 -> 0 | V13: =(S13+U13)*4% -> 30349.02 | W13: =(S13+U13)*4% -> 30349.02 | Y13: =+V13+W13+X13 -> 60698.04 | Z13: =+S13+T13+U13-Y13 -> 698027.46
A14: 6 | B14: =+Asistencia!B8 -> CHRISTIAN STIVEN GIRON POSADA | C14: =+Asistencia!C8 -> 1114620530 | D14: =+'Desprendible FIJOS'!E74 -> 0 | E14: =+'Desprendible FIJOS'!E75 -> 0 | H14: =(E14+G14)*4% -> 0 | I14: =(E14+G14)*4% -> 0 | K14: =+H14+I14+J14 -> 0 | L14: =+E14+F14+G14-K14 -> 0 | O14: 6 | P14: =+Asistencia!B8 -> CHRISTIAN STIVEN GIRON POSADA | Q14: =+Asistencia!C8 -> 1114620530 | R14: =+'Desprendible FIJOS'!J74 -> 13 | S14: =+'Desprendible FIJOS'!J75 -> 758725.5 | T14: 0 | V14: =+'Desprendible FIJOS'!J76 -> 30349.02 | W14: =+'Desprendible FIJOS'!J77 -> 30349.02 | Y14: =+V14+W14+X14 -> 60698.04 | Z14: =+S14+T14+U14-Y14 -> 698027.46
B15: VALOR TOTAL | E15: =SUM(E9:E14) -> 0 | F15: =SUM(F9:F14) -> 0 | G15: =SUM(G9:G14) -> 0 | H15: =SUM(H9:H14) -> 0 | I15: =SUM(I9:I14) -> 0 | J15: =SUM(J9:J14) -> 0 | K15: =SUM(K9:K14) -> 0 | L15: =SUM(L9:L14) -> 0
P16: VALOR TOTAL | S16: =SUM(S9:S14) -> 4552353 | T16: =SUM(T9:T14) -> 0 | U16: =SUM(U9:U14) -> 0 | V16: =SUM(V9:V14) -> 182094.12 | W16: =SUM(W9:W14) -> 182094.12 | X16: =SUM(X9:X14) -> 0 | Y16: =SUM(Y9:Y14) -> 364188.24 | Z16: =SUM(Z9:Z14) -> 4188164.8
B18: ELABORADO POR | D18: APROBADO POR | I18: REVISADO POR
P19: ELABORADO POR | R19: APROBADO POR | V19: REVISADO
B22: DEVENGADO | C22: =+E15+F15+G15 -> 0
B23: NETO PAGADO | C23: =+L15 -> 0 | P23: DEVENGADO | Q23: =+S16+T16+U16 -> 4552353
P24: NETO PAGADO | Q24: =+Z16 -> 4188164.8

Sheet SEG SOCIAL
C4: SALARIO AÑO-2026 | D4: 1750905
C5: PENSION | D5: 280200
C6: ARL | D6: 42700
C7: CAJA | D7: 70100
C8: EPS | D8: 70100 | E8: OPERATIVO
D9: =SUM(D5:D8) -> 463100 | E9: cristian
E10: jose manuel
E11: leandro melo
C15: SALARIO AÑO-2026 | D15: 1750905
C16: PENSION | D16: 280200
C17: ARL | D17: 9200
C18: CAJA | D18: 70100
C19: EPS | D19: 70100 | E19: ADMINISTRATIVO
D20: =SUM(D16:D19) -> 429600 | E20: KEVIN
E21: FELIPE
E22: VICTORIA
